Workbook

Sheet BOM-Multi
A1: รหัสสินค้า | B1: สูตรนี้สำหรับ | C1: รหัสวัตถุดิบ | D1: ชื่อวัตถุดิบ | E1: จำนวน | F1: หมายเหตุ
A2: WKB-0002 | B2: 5760 | C2: M01-0004 | D2: =IF(C2="","",INDEX(รายการวัตถุดิบ!B:B,MATCH('BOM-Multi'!C2,รายการวัตถุดิบ!A:A,0))) -> น้ำตาลทราย | E2: 15 | F2: สูตร1 | L2: รหัสวัตถุดิบ | M2: ชื่อวัตถุดิบ | N2: หน่วย
A3: WKB-0002 | B3: 5760 | C3: M03-0022 | D3: =IF(C3="","",INDEX(รายการวัตถุดิบ!B:B,MATCH('BOM-Multi'!C3,รายการวัตถุดิบ!A:A,0))) -> แป้งสาลี D-1 | E3: 192 | F3: สูตร1 | L3: =IF(OR(M3="-",M3=""),"-",INDEX(รายการวัตถุดิบ!$A:$A,MATCH(M3,รายการวัตถุดิบ!$B:$B,0))) -> - | N3: =IF(OR(M3="-",M3=""),"-",INDEX(รายการวัตถุดิบ!$C:$C,MATCH(M3,รายการวัตถุดิบ!$B:$B,0))) -> -
A4: WKB-0002 | B4: 5760 | C4: M04-0012 | D4: =IF(C4="","",INDEX(รายการวัตถุดิบ!B:B,MATCH('BOM-Multi'!C4,รายการวัตถุดิบ!A:A,0))) -> เกลือแป้ง 50 กก./ถุง | E4: 1 | F4: สูตร1 | L4: =IF(OR(M4="-",M4=""),"-",INDEX(รายการวัตถุดิบ!$A:$A,MATCH(M4,รายการวัตถุดิบ!$B:$B,0))) -> - | N4: =IF(OR(M4="-",M4=""),"-",INDEX(รายการวัตถุดิบ!$C:$C,MATCH(M4,รายการวัตถุดิบ!$B:$B,0))) -> -
A5: WKB-0002 | B5: 5760 | C5: M04-0016 | D5: =IF(C5="","",INDEX(รายการวัตถุดิบ!B:B,MATCH('BOM-Multi'!C5,รายการวัตถุดิบ!A:A,0))) -> โซเดียมไบคาร์บอเนต | E5: 1 | F5: สูตร1 | L5: =IF(OR(M5="-",M5=""),"-",INDEX(รายการวัตถุดิบ!$A:$A,MATCH(M5,รายการวัตถุดิบ!$B:$B,0))) -> - | N5: =IF(OR(M5="-",M5=""),"-",INDEX(รายการวัตถุดิบ!$C:$C,MATCH(M5,รายการวัตถุดิบ!$B:$B,0))) -> -
A6: WKB-0002 | B6: 5760 | C6: M04-0027 | D6: =IF(C6="","",INDEX(รายการวัตถุดิบ!B:B,MATCH('BOM-Multi'!C6,รายการวัตถุดิบ!A:A,0))) -> LIQUID GLUCOSE | E6: 7 | F6: สูตร1 | L6: =IF(OR(M6="-",M6=""),"-",INDEX(รายการวัตถุดิบ!$A:$A,MATCH(M6,รายการวัตถุดิบ!$B:$B,0))) -> - | N6: =IF(OR(M6="-",M6=""),"-",INDEX(รายการวัตถุดิบ!$C:$C,MATCH(M6,รายการวัตถุดิบ!$B:$B,0))) -> -
A7: WKB-0002 | B7: 5760 | C7: M04-0030 | D7: =IF(C7="","",INDEX(รายการวัตถุดิบ!B:B,MATCH('BOM-Multi'!C7,รายการวัตถุดิบ!A:A,0))) -> แอมโมเนียม | E7: 25 | F7: สูตร1 | L7: =IF(OR(M7="-",M7=""),"-",INDEX(รายการวัตถุดิบ!$A:$A,MATCH(M7,รายการวัตถุดิบ!$B:$B,0))) -> - | N7: =IF(OR(M7="-",M7=""),"-",INDEX(รายการวัตถุดิบ!$C:$C,MATCH(M7,รายการวัตถุดิบ!$B:$B,0))) -> -
A8: WKB-0002 | B8: 5760 | C8: M04-0079 | D8: =IF(C8="","",INDEX(รายการวัตถุดิบ!B:B,MATCH('BOM-Multi'!C8,รายการวัตถุดิบ!A:A,0))) -> MENARA EIFEL MARGARINE | E8: 27 | F8: สูตร1 | L8: =IF(OR(M8="-",M8=""),"-",INDEX(รายการวัตถุดิบ!$A:$A,MATCH(M8,รายการวัตถุดิบ!$B:$B,0))) -> - | N8: =IF(OR(M8="-",M8=""),"-",INDEX(รายการวัตถุดิบ!$C:$C,MATCH(M8,รายการวัตถุดิบ!$B:$B,0))) -> -
A9: WKB-0002 | B9: 5760 | C9: M04-0089 | D9: =IF(C9="","",INDEX(รายการวัตถุดิบ!B:B,MATCH('BOM-Multi'!C9,รายการวัตถุดิบ!A:A,0))) -> ยีส | E9: 1 | F9: สูตร1 | L9: =IF(OR(M9="-",M9=""),"-",INDEX(รายการวัตถุดิบ!$A:$A,MATCH(M9,รายการวัตถุดิบ!$B:$B,0))) -> - | N9: =IF(OR(M9="-",M9=""),"-",INDEX(รายการวัตถุดิบ!$C:$C,MATCH(M9,รายการวัตถุดิบ!$B:$B,0))) -> -
A10: WKB-0002 | B10: 5760 | C10: M04-0094 | D10: =IF(C10="","",INDEX(รายการวัตถุดิบ!B:B,MATCH('BOM-Multi'!C10,รายการวัตถุดิบ!A:A,0))) -> Coconut cream powder (ผงกะทิ) | E10: 3 | F10: สูตร1 | L10: =IF(OR(M10="-",M10=""),"-",INDEX(รายการวัตถุดิบ!$A:$A,MATCH(M10,รายการวัตถุดิบ!$B:$B,0))) -> - | N10: =IF(OR(M10="-",M10=""),"-",INDEX(รายการวัตถุดิบ!$C:$C,MATCH(M10,รายการวัตถุดิบ!$B:$B,0))) -> -
A11: WKB-0002 | B11: 5760 | C11: M04-0134 | D11: =IF(C11="","",INDEX(รายการวัตถุดิบ!B:B,MATCH('BOM-Multi'!C11,รายการวัตถุดิบ!A:A,0))) -> ผงฟูเอส (25kg.) | E11: 2 | F11: สูตร1 | L11: =IF(OR(M11="-",M11=""),"-",INDEX(รายการวัตถุดิบ!$A:$A,MATCH(M11,รายการวัตถุดิบ!$B:$B,0))) -> - | N11: =IF(OR(M11="-",M11=""),"-",INDEX(รายการวัตถุดิบ!$C:$C,MATCH(M11,รายการวัตถุดิบ!$B:$B,0))) -> -
A12: WKB-0002 | B12: 5760 | C12: M04-0135 | D12: =IF(C12="","",INDEX(รายการวัตถุดิบ!B:B,MATCH('BOM-Multi'!C12,รายการวัตถุดิบ!A:A,0))) -> Amylase 5000SKB | E12: 1 | F12: สูตร1 | L12: =IF(OR(M12="-",M12=""),"-",INDEX(รายการวัตถุดิบ!$A:$A,MATCH(M12,รายการวัตถุดิบ!$B:$B,0))) -> - | N12: =IF(OR(M12="-",M12=""),"-",INDEX(รายการวัตถุดิบ!$C:$C,MATCH(M12,รายการวัตถุดิบ!$B:$B,0))) -> -
A13: WKB-0002 | B13: 5760 | C13: M05-0006 | D13: =IF(C13="","",INDEX(รายการวัตถุดิบ!B:B,MATCH('BOM-Multi'!C13,รายการวัตถุดิบ!A:A,0))) -> SUNSET YELLOW สีส้ม ละลายน้ำ | E13: 0.1 | F13: สูตร1 | L13: =IF(OR(M13="-",M13=""),"-",INDEX(รายการวัตถุดิบ!$A:$A,MATCH(M13,รายการวัตถุดิบ!$B:$B,0))) -> - | N13: =IF(OR(M13="-",M13=""),"-",INDEX(รายการวัตถุดิบ!$C:$C,MATCH(M13,รายการวัตถุดิบ!$B:$B,0))) -> -
A14: WKB-0002 | B14: 5760 | C14: M05-0016 | D14: =IF(C14="","",INDEX(รายการวัตถุดิบ!B:B,MATCH('BOM-Multi'!C14,รายการวัตถุดิบ!A:A,0))) -> กลิ่นมะพร้าว Coconut Flavour A1401412 | E14: 3.5 | F14: สูตร1 | L14: =IF(OR(M14="-",M14=""),"-",INDEX(รายการวัตถุดิบ!$A:$A,MATCH(M14,รายการวัตถุดิบ!$B:$B,0))) -> - | N14: =IF(OR(M14="-",M14=""),"-",INDEX(รายการวัตถุดิบ!$C:$C,MATCH(M14,รายการวัตถุดิบ!$B:$B,0))) -> -
... A17: WKB-0002 | B17: 5760 | C17: M05-0101 | D17: =IF(C17="","",INDEX(รายการวัตถุดิบ!B:B,MATCH('BOM-Multi'!C17,รายการวัตถุดิบ!A:A,0))) -> Sweet Whey Powder DMK (หางนม 3) ขนาดบรรจุ 25 กก. | E17: 3 | F17: สูตร1 | L17: =IF(OR(M17="-",M17=""),"-",INDEX(รายการวัตถุดิบ!$A:$A,MATCH(M17,รายการวัตถุดิบ!$B:$B,0))) -> - | N17: =IF(OR(M17="-",M17=""),"-",INDEX(รายการวัตถุดิบ!$C:$C,MATCH(M17,รายการวัตถุดิบ!$B:$B,0))) -> -
D19: =IF(C19="","",INDEX(รายการวัตถุดิบ!B:B,MATCH('BOM-Multi'!C19,รายการวัตถุดิบ!A:A,0))) | F19: สูตร 2 | L19: =IF(OR(M19="-",M19=""),"-",INDEX(รายการวัตถุดิบ!$A:$A,MATCH(M19,รายการวัตถุดิบ!$B:$B,0))) -> - | N19: =IF(OR(M19="-",M19=""),"-",INDEX(รายการวัตถุดิบ!$C:$C,MATCH(M19,รายการวัตถุดิบ!$B:$B,0))) -> -
A20: WKB-0002 | B20: 5760 | C20: M01-0004 | D20: =IF(C20="","",INDEX(รายการวัตถุดิบ!B:B,MATCH('BOM-Multi'!C20,รายการวัตถุดิบ!A:A,0))) -> น้ำตาลทราย | E20: 15 | F20: สูตร 2 | L20: =IF(OR(M20="-",M20=""),"-",INDEX(รายการวัตถุดิบ!$A:$A,MATCH(M20,รายการวัตถุดิบ!$B:$B,0))) -> - | N20: =IF(OR(M20="-",M20=""),"-",INDEX(รายการวัตถุดิบ!$C:$C,MATCH(M20,รายการวัตถุดิบ!$B:$B,0))) -> -
A21: WKB-0002 | B21: 5760 | C21: M03-0022 | D21: =IF(C21="","",INDEX(รายการวัตถุดิบ!B:B,MATCH('BOM-Multi'!C21,รายการวัตถุดิบ!A:A,0))) -> แป้งสาลี D-1 | E21: 192 | F21: สูตร 2 | L21: =IF(OR(M21="-",M21=""),"-",INDEX(รายการวัตถุดิบ!$A:$A,MATCH(M21,รายการวัตถุดิบ!$B:$B,0))) -> - | N21: =IF(OR(M21="-",M21=""),"-",INDEX(รายการวัตถุดิบ!$C:$C,MATCH(M21,รายการวัตถุดิบ!$B:$B,0))) -> -
A22: WKB-0002 | B22: 5760 | C22: M04-0012 | D22: =IF(C22="","",INDEX(รายการวัตถุดิบ!B:B,MATCH('BOM-Multi'!C22,รายการวัตถุดิบ!A:A,0))) -> เกลือแป้ง 50 กก./ถุง | E22: 1 | F22: สูตร 2 | L22: =IF(OR(M22="-",M22=""),"-",INDEX(รายการวัตถุดิบ!$A:$A,MATCH(M22,รายการวัตถุดิบ!$B:$B,0))) -> - | N22: =IF(OR(M22="-",M22=""),"-",INDEX(รายการวัตถุดิบ!$C:$C,MATCH(M22,รายการวัตถุดิบ!$B:$B,0))) -> -
A23: WKB-0002 | B23: 5760 | C23: M04-0016 | D23: =IF(C23="","",INDEX(รายการวัตถุดิบ!B:B,MATCH('BOM-Multi'!C23,รายการวัตถุดิบ!A:A,0))) -> โซเดียมไบคาร์บอเนต | E23: 1 | F23: สูตร 2 | L23: =IF(OR(M23="-",M23=""),"-",INDEX(รายการวัตถุดิบ!$A:$A,MATCH(M23,รายการวัตถุดิบ!$B:$B,0))) -> - | N23: =IF(OR(M23="-",M23=""),"-",INDEX(รายการวัตถุดิบ!$C:$C,MATCH(M23,รายการวัตถุดิบ!$B:$B,0))) -> -
A24: WKB-0002 | B24: 5760 | C24: M04-0027 | D24: =IF(C24="","",INDEX(รายการวัตถุดิบ!B:B,MATCH('BOM-Multi'!C24,รายการวัตถุดิบ!A:A,0))) -> LIQUID GLUCOSE | E24: 7 | F24: สูตร 2 | L24: =IF(OR(M24="-",M24=""),"-",INDEX(รายการวัตถุดิบ!$A:$A,MATCH(M24,รายการวัตถุดิบ!$B:$B,0))) -> - | N24: =IF(OR(M24="-",M24=""),"-",INDEX(รายการวัตถุดิบ!$C:$C,MATCH(M24,รายการวัตถุดิบ!$B:$B,0))) -> -
A25: WKB-0002 | B25: 5760 | C25: M04-0030 | D25: =IF(C25="","",INDEX(รายการวัตถุดิบ!B:B,MATCH('BOM-Multi'!C25,รายการวัตถุดิบ!A:A,0))) -> แอมโมเนียม | E25: 25 | F25: สูตร 2 | L25: =IF(OR(M25="-",M25=""),"-",INDEX(รายการวัตถุดิบ!$A:$A,MATCH(M25,รายการวัตถุดิบ!$B:$B,0))) -> - | N25: =IF(OR(M25="-",M25=""),"-",INDEX(รายการวัตถุดิบ!$C:$C,MATCH(M25,รายการวัตถุดิบ!$B:$B,0))) -> -
A26: WKB-0002 | B26: 5760 | C26: M04-0073-1 | D26: =IF(C26="","",INDEX(รายการวัตถุดิบ!B:B,MATCH('BOM-Multi'!C26,รายการวัตถุดิบ!A:A,0))) -> ไขมัน MENARA SHORTENING BLU 39-42 (16kg.) | E26: 25 | F26: สูตร 2 | L26: =IF(OR(M26="-",M26=""),"-",INDEX(รายการวัตถุดิบ!$A:$A,MATCH(M26,รายการวัตถุดิบ!$B:$B,0))) -> - | N26: =IF(OR(M26="-",M26=""),"-",INDEX(รายการวัตถุดิบ!$C:$C,MATCH(M26,รายการวัตถุดิบ!$B:$B,0))) -> -
A27: WKB-0002 | B27: 5760 | C27: M04-0089 | D27: =IF(C27="","",INDEX(รายการวัตถุดิบ!B:B,MATCH('BOM-Multi'!C27,รายการวัตถุดิบ!A:A,0))) -> ยีส | E27: 1 | F27: สูตร 2 | L27: =IF(OR(M27="-",M27=""),"-",INDEX(รายการวัตถุดิบ!$A:$A,MATCH(M27,รายการวัตถุดิบ!$B:$B,0))) -> - | N27: =IF(OR(M27="-",M27=""),"-",INDEX(รายการวัตถุดิบ!$C:$C,MATCH(M27,รายการวัตถุดิบ!$B:$B,0))) -> -
A28: WKB-0002 | B28: 5760 | C28: M04-0094 | D28: =IF(C28="","",INDEX(รายการวัตถุดิบ!B:B,MATCH('BOM-Multi'!C28,รายการวัตถุดิบ!A:A,0))) -> Coconut cream powder (ผงกะทิ) | E28: 3 | F28: สูตร 2
A29: WKB-0002 | B29: 5760 | C29: M04-0134 | D29: =IF(C29="","",INDEX(รายการวัตถุดิบ!B:B,MATCH('BOM-Multi'!C29,รายการวัตถุดิบ!A:A,0))) -> ผงฟูเอส (25kg.) | E29: 2 | F29: สูตร 2
A30: WKB-0002 | B30: 5760 | C30: M04-0135 | D30: =IF(C30="","",INDEX(รายการวัตถุดิบ!B:B,MATCH('BOM-Multi'!C30,รายการวัตถุดิบ!A:A,0))) -> Amylase 5000SKB | E30: 1 | F30: สูตร 2
A31: WKB-0002 | B31: 5760 | C31: M05-0006 | D31: =IF(C31="","",INDEX(รายการวัตถุดิบ!B:B,MATCH('BOM-Multi'!C31,รายการวัตถุดิบ!A:A,0))) -> SUNSET YELLOW สีส้ม ละลายน้ำ | E31: 0.1 | F31: สูตร 2
A32: WKB-0002 | B32: 5760 | C32: M05-0016 | D32: =IF(C32="","",INDEX(รายการวัตถุดิบ!B:B,MATCH('BOM-Multi'!C32,รายการวัตถุดิบ!A:A,0))) -> กลิ่นมะพร้าว Coconut Flavour A1401412 | E32: 3.5 | F32: สูตร 2
A33: WKB-0002 | B33: 5760 | C33: M05-0020 | D33: =IF(C33="","",INDEX(รายการวัตถุดิบ!B:B,MATCH('BOM-Multi'!C33,รายการวัตถุดิบ!A:A,0))) -> 860300M Eurocert Tartrazine สีเหลือง | E33: 0.2 | F33: สูตร 2
A34: WKB-0002 | B34: 5760 | C34: M05-0058 | D34: =IF(C34="","",INDEX(รายการวัตถุดิบ!B:B,MATCH('BOM-Multi'!C34,รายการวัตถุดิบ!A:A,0))) -> Sodium Acid pyrophosphate(SAPP) | E34: 2 | F34: สูตร 2
A35: WKB-0002 | B35: 5760 | C35: M05-0101 | D35: =IF(C35="","",INDEX(รายการวัตถุดิบ!B:B,MATCH('BOM-Multi'!C35,รายการวัตถุดิบ!A:A,0))) -> Sweet Whey Powder DMK (หางนม 3) ขนาดบรรจุ 25 กก. | E35: 3 | F35: สูตร 2
D36: =IF(C36="","",INDEX(รายการวัตถุดิบ!B:B,MATCH('BOM-Multi'!C36,รายการวัตถุดิบ!A:A,0)))
D37: =IF(C37="","",INDEX(รายการวัตถุดิบ!B:B,MATCH('BOM-Multi'!C37,รายการวัตถุดิบ!A:A,0)))
D38: =IF(C38="","",INDEX(รายการวัตถุดิบ!B:B,MATCH('BOM-Multi'!C38,รายการวัตถุดิบ!A:A,0)))
D39: =IF(C39="","",INDEX(รายการวัตถุดิบ!B:B,MATCH('BOM-Multi'!C39,รายการวัตถุดิบ!A:A,0)))
D40: =IF(C40="","",INDEX(รายการวัตถุดิบ!B:B,MATCH('BOM-Multi'!C40,รายการวัตถุดิบ!A:A,0)))
D41: =IF(C41="","",INDEX(รายการวัตถุดิบ!B:B,MATCH('BOM-Multi'!C41,รายการวัตถุดิบ!A:A,0)))
D42: =IF(C42="","",INDEX(รายการวัตถุดิบ!B:B,MATCH('BOM-Multi'!C42,รายการวัตถุดิบ!A:A,0)))
D43: =IF(C43="","",INDEX(รายการวัตถุดิบ!B:B,MATCH('BOM-Multi'!C43,รายการวัตถุดิบ!A:A,0)))
...

Sheet Sheet2
A1: รหัสสินค้า | B1: สูตรนี้สำหรับ | C1: รหัสวัตถุดิบ | D1: ชื่อวัตถุดิบ | E1: จำนวน | F1: หมายเหตุ
A2: WKB-0002 | B2: 5760 | C2: M01-0004 | D2: =IF(C2="","",INDEX(รายการวัตถุดิบ!B:B,MATCH('BOM-Multi'!C1,รายการวัตถุดิบ!A:A,0))) -> ชื่อวัตถุดิบ | E2: 15
A3: WKB-0002 | B3: 5760 | C3: M03-0017 | D3: =IF(C3="","",INDEX(รายการวัตถุดิบ!B:B,MATCH('BOM-Multi'!C2,รายการวัตถุดิบ!A:A,0))) -> น้ำตาลทราย | E3: 0
A4: WKB-0002 | B4: 5760 | C4: M03-0022 | D4: =IF(C4="","",INDEX(รายการวัตถุดิบ!B:B,MATCH('BOM-Multi'!#REF!,รายการวัตถุดิบ!A:A,0))) -> #REF! | E4: 192
A5: WKB-0002 | B5: 5760 | C5: M04-0006 | D5: =IF(C5="","",INDEX(รายการวัตถุดิบ!B:B,MATCH('BOM-Multi'!C3,รายการวัตถุดิบ!A:A,0))) -> แป้งสาลี D-1 | E5: 30
A6: WKB-0002 | B6: 5760 | C6: M04-0012 | D6: =IF(C6="","",INDEX(รายการวัตถุดิบ!B:B,MATCH('BOM-Multi'!#REF!,รายการวัตถุดิบ!A:A,0))) -> #REF! | E6: 3
A7: WKB-0002 | B7: 5760 | C7: M04-0016 | D7: =IF(C7="","",INDEX(รายการวัตถุดิบ!B:B,MATCH('BOM-Multi'!C4,รายการวัตถุดิบ!A:A,0))) -> เกลือแป้ง 50 กก./ถุง | E7: 1
A8: WKB-0002 | B8: 5760 | C8: M04-0027 | D8: =IF(C8="","",INDEX(รายการวัตถุดิบ!B:B,MATCH('BOM-Multi'!C5,รายการวัตถุดิบ!A:A,0))) -> โซเดียมไบคาร์บอเนต | E8: 7
A9: WKB-0002 | B9: 5760 | C9: M04-0030 | D9: =IF(C9="","",INDEX(รายการวัตถุดิบ!B:B,MATCH('BOM-Multi'!C6,รายการวัตถุดิบ!A:A,0))) -> LIQUID GLUCOSE | E9: 25
A10: WKB-0002 | B10: 5760 | C10: M04-0079 | D10: =IF(C10="","",INDEX(รายการวัตถุดิบ!B:B,MATCH('BOM-Multi'!C7,รายการวัตถุดิบ!A:A,0))) -> แอมโมเนียม | E10: 27
A11: WKB-0002 | B11: 5760 | C11: M04-0073-1 | D11: =IF(C11="","",INDEX(รายการวัตถุดิบ!B:B,MATCH('BOM-Multi'!C8,รายการวัตถุดิบ!A:A,0))) -> MENARA EIFEL MARGARINE | E11: 1
A12: WKB-0002 | B12: 5760 | C12: M04-0094 | D12: =IF(C12="","",INDEX(รายการวัตถุดิบ!B:B,MATCH('BOM-Multi'!C9,รายการวัตถุดิบ!A:A,0))) -> ยีส | E12: 3
A13: WKB-0002 | B13: 5760 | C13: M04-0134 | D13: =IF(C13="","",INDEX(รายการวัตถุดิบ!B:B,MATCH('BOM-Multi'!C10,รายการวัตถุดิบ!A:A,0))) -> Coconut cream powder (ผงกะทิ) | E13: 2
A14: WKB-0002 | B14: 5760 | C14: M04-0135 | D14: =IF(C14="","",INDEX(รายการวัตถุดิบ!B:B,MATCH('BOM-Multi'!C11,รายการวัตถุดิบ!A:A,0))) -> ผงฟูเอส (25kg.) | E14: 1
A15: WKB-0002 | B15: 5760 | C15: M04-0152 | D15: =IF(C15="","",INDEX(รายการวัตถุดิบ!B:B,MATCH('BOM-Multi'!C12,รายการวัตถุดิบ!A:A,0))) -> Amylase 5000SKB | E15: 0
A16: WKB-0002 | B16: 5760 | C16: M05-0006 | D16: =IF(C16="","",INDEX(รายการวัตถุดิบ!B:B,MATCH('BOM-Multi'!#REF!,รายการวัตถุดิบ!A:A,0))) -> #REF! | E16: 0.1
A17: WKB-0002 | B17: 5760 | C17: M05-0016 | D17: =IF(C17="","",INDEX(รายการวัตถุดิบ!B:B,MATCH('BOM-Multi'!C13,รายการวัตถุดิบ!A:A,0))) -> SUNSET YELLOW สีส้ม ละลายน้ำ | E17: 3.5
A18: WKB-0002 | B18: 5760 | C18: M05-0020 | D18: =IF(C18="","",INDEX(รายการวัตถุดิบ!B:B,MATCH('BOM-Multi'!C14,รายการวัตถุดิบ!A:A,0))) -> กลิ่นมะพร้าว Coconut Flavour A1401412 | E18: 0.2
A19: WKB-0002 | B19: 5760 | C19: M05-0058 | D19: =IF(C19="","",INDEX(รายการวัตถุดิบ!B:B,MATCH('BOM-Multi'!C15,รายการวัตถุดิบ!A:A,0))) -> 860300M Eurocert Tartrazine สีเหลือง | E19: 2
A20: WKB-0002 | B20: 5760 | C20: M05-0101 | D20: =IF(C20="","",INDEX(รายการวัตถุดิบ!B:B,MATCH('BOM-Multi'!C16,รายการวัตถุดิบ!A:A,0))) -> Sodium Acid pyrophosphate(SAPP) | E20: 3

Sheet วิธีกรอก
A1: คู่มือการกรอกเทมเพลต BOM ในหน้า BOM-Multi
A2: หัวข้อ | B2: รายละเอียด | C2: ตัวอย่าง
A3: ภาพรวม | B3: เทมเพลตนี้ใช้สำหรับนำเข้า BOM หลายสินค้าในครั้งเดียว โปรดกรอกตามหัวคอลัมน์ให้ครบถ้วน โดยแต่ละแถวคือวัตถุดิบหนึ่งรายการของสินค้า | C3: รหัสสินค้า | D3: สูตรนี้สำหรับกี่กล่อง | E3: รหัสวัตถุดิบ | F3: จำนวน | G3: หมายเหตุ
A4: รหัสสินค้า | B4: ต้องเป็นรหัสสินค้าที่มีอยู่ในระบบ (ตัวอย่าง: FG-1001) หากไม่พบรหัสสินค้า ระบบจะไม่นำเข้าแถวนั้น | C4: BL0-5010 | D4: 285 | E4: N15-0002 | F4: 1
A5: สูตรนี้สำหรับกี่กล่อง | B5: บังคับกรอกและต้องมากกว่า 0 ใช้เป็นฐานคำนวณสูตรต่อสินค้า หากสินค้าเดียวกันมีหลายแถว ให้กรอกจำนวนกล่องให้ตรงกันทุกแถว | C5: BL0-5010 | D5: 285 | E5: P18-0002-1 | F5: 285
A6: รหัสวัตถุดิบ | B6: ต้องเป็นรหัสวัตถุดิบที่มีอยู่ในระบบ (ตัวอย่าง: RM-001) หากไม่พบรหัสวัตถุดิบ ระบบจะไม่นำเข้าแถวนั้น | C6: BL0-5010 | D6: 285 | E6: S01-0284 | F6: 285
A7: จำนวน | B7: บังคับกรอกและต้องมากกว่า 0 สามารถเป็นเลขทศนิยมได้ เช่น 1.5 | C7: BL0-5010 | D7: 285 | E7: S01-0286 | F7: 285
A8: หมายเหตุ | B8: ไม่บังคับ ใช้สำหรับอธิบายเพิ่มเติม เช่น สูตรหลัก, สีเข้ม, บรรจุภัณฑ์/ลังละ 12 | C8: BL0-5010 | D8: 285 | E8: S02-0010 | F8: 285
C9: BL0-5010 | D9: 285 | E9: S02-0013 | F9: 1
C10: BL0-5010 | D10: 285 | E10: S03-0001-1 | F10: 4
A11: ตัวอย่างในตาราง คือ ในการผลิต ขนมปังกรอบรสงา 5 กก. จำนวน 285 ปี๊บ ต้องใช้วัตถุดิบ N15-0002 ฟิล์มยืดเอ็มเสตรช จำนวน 1 P18-0002-1 ปี๊บใหญ่ หน้ากระจก พร้อมฝา (Size XL) จำนวน 285 S01-0284 KL - ฉลากติดปี๊บขนมปังรสงา XL 4 สี ขนาด 7x17cm. จำนวน 285 S01-0286 KL - Sticker ขนมปังกรอบรสงา พิมพ์ 1 สี size XL จำนวน 285 S02-0010 สายคาดปี๊บ จำนวน 285 S02-0013 สายรัดกล่องสีน้ำเงิน พิมพ์ตรา KPF 8 KG จำนวน 1 S03-0001-1 กาวแท่งสีขุ่น (1kg.x34แท่ง) จำนวน 4 S04-0003-1 PP - ใส แผ่น 29*30*0.03 cm. (ใบตองปี๊บใหญ่) จำนวน 2 S05-0002 KL-Barcode ขนมปังกรอบรสงา (5kg.) จำนวน 285 WKB-0047 แครกเกอร์สี่เหลี่ยมยาว (ออพาย) 26-12-68 จำนวน 1425 | C11: BL0-5010 | D11: 285 | E11: S04-0003-1 | F11: 2
C12: BL0-5010 | D12: 285 | E12: S05-0002 | F12: 285
C13: BL0-5010 | D13: 285 | E13: WKB-0047 | F13: 1425

Sheet รายการสินค้า
A1: รหัสสินค้า | B1: ชื่อสินค้า | C1: หน่วย
A2: B01-0013 | B2: แม่มะลิ คุกกี้ ทุเรียน 5 กก. (1 ปี๊บ) | C2: ปี๊บ
A3: B01-0015 | B3: แม่มะลิ คุกกี้ ช็อก 5 กก. (1 ปี๊บ) | C3: ปี๊บ
A4: B01-1001 | B4: แม่มะลิ คุกกี้ วานิลลา 5 กก. (1 ปี๊บ) | C4: ปี๊บ(5กก.)
A5: B01-1002 | B5: แม่มะลิ คุกกี้ สตรอ 5 กก. (1 ปี๊บ) | C5: ปี๊บ
A6: B01-1008 | B6: แม่มะลิ สมุย รสมะพร้าว 5 กก. (1 ปี๊บ) | C6: ปี๊บ/5กก.
A7: B01-1009 | B7: แม่มะลิ งาหอม รสงา 5 กก. (1 ปี๊บ) | C7: ปี๊บ/5กก.
A8: B01-1011 | B8: แม่มะลิ ก้นหอย กาแฟ 5 กก. (1 ปี๊บ) | C8: ปี๊บ/5กก.
A9: B01-1012 | B9: แม่มะลิ ก้นหอย เลม่อน 5 กก. (1 ปี๊บ) | C9: ปี๊บ/5กก.
A10: B01-1013 | B10: แม่มะลิ ก้นหอย ใบเตย 5 กก. (1 ปี๊บ) | C10: ปี๊บ/5กก.
A11: B01-1014 | B11: แม่มะลิ ตาข่าย ใบเตย 5 กก. (1 ปี๊บ) | C11: ปี๊บ/5กก.
A12: B01-1015 | B12: แม่มะลิ ตาข่าย วานิลลา 5 กก. (1 ปี๊บ) | C12: ปี๊บ/5กก.
... A637: Z04-0002 | B637: ตัวดิบ pellet 4 layer(ผ่านกระบวนการ second dryer) | C637: KG

Sheet รายการวัตถุดิบ
A1: รหัสวัตถุดิบ | B1: ชื่อวัตถุดิบ | C1: หน่วย
A2: C01-001 | B2: สกรูเกลียว. | C2: ชุด
A3: C02-001 | B3: แก๊ส LPG 1 วาล์ว | C3: ถัง/48กก.
A4: C02-002 | B4: แก๊ส LPG 2 วาล์ว | C4: ถัง/48กก.
A5: C02-003 | B5: แก๊สปิโตรเลี่ยมเหลว (Bulk LPG) | C5: กิโลกรัม
A6: C03-001 | B6: กระดาษ | C6: ม้วน
A7: DC-001 | B7: ค่าขนส่งน้ำตาลทราย | C7: ครั้ง
A8: E-0001 | B8: วัสดุอุปกรณ์ | C8: PCS
A9: E-0045 | B9: ผ้าหมึก ERC-05 | C9: ชิ้น
A10: EU-0007 | B10: CHEMTREAT CON ALK-110 | C10: KGS
A11: M-BEL-05-28 | B11: สายพาน PU หนา1.5mm. w=610mm. L=3520mm. | C11: เส้น
A12: M00-0001 | B12: เบาะแซ | C12: ก.ล.x24กก.
... A2412: Z04-0002 | B2412: ตัวดิบ pellet 4 layer(ผ่านกระบวนการ second dryer) | C2412: KG

Sheet Sheet1
E1: รหัสวัตถุดิบ | F1: ชื่อวัตถุดิบ | G1: หน่วย
A2: คำที่ต้องการหา | B2: สาลี | E2: =IF(OR(F2="-",F2=""),"-",INDEX(รายการวัตถุดิบ!$A:$A,MATCH(F2,รายการวัตถุดิบ!$B:$B,0))) -> M03-0001 | F2: {=IF(B2="","-",_xlfn._xlws.FILTER(รายการวัตถุดิบ!$B:$B,ISNUMBER(SEARCH(B2,รายการวัตถุดิบ!$B:$B))))} -> แป้งสาลี | G2: =IF(OR(F2="-",F2=""),"-",INDEX(รายการวัตถุดิบ!$C:$C,MATCH(F2,รายการวัตถุดิบ!$B:$B,0))) -> ถุงx22.50 | J2: หน่วย | K2: unit
E3: =IF(OR(F3="-",F3=""),"-",INDEX(รายการวัตถุดิบ!$A:$A,MATCH(F3,รายการวัตถุดิบ!$B:$B,0))) -> M03-0004 | F3: แป้งสาลี NEOVIS T-205 | G3: =IF(OR(F3="-",F3=""),"-",INDEX(รายการวัตถุดิบ!$C:$C,MATCH(F3,รายการวัตถุดิบ!$B:$B,0))) -> ถุง | J3: kg | K3: 1
E4: =IF(OR(F4="-",F4=""),"-",INDEX(รายการวัตถุดิบ!$A:$A,MATCH(F4,รายการวัตถุดิบ!$B:$B,0))) -> M03-0007 | F4: แป้งสาลี**บางกอก ฟลาว มิลล์** | G4: =IF(OR(F4="-",F4=""),"-",INDEX(รายการวัตถุดิบ!$C:$C,MATCH(F4,รายการวัตถุดิบ!$B:$B,0))) -> ถุงx22.50 | J4: ถุงละ 10 kg | K4: 10 | L4: kg
E5: =IF(OR(F5="-",F5=""),"-",INDEX(รายการวัตถุดิบ!$A:$A,MATCH(F5,รายการวัตถุดิบ!$B:$B,0))) -> M03-0008 | F5: แป้งสาลี KH เหลือง โปรตีนสูง | G5: =IF(OR(F5="-",F5=""),"-",INDEX(รายการวัตถุดิบ!$C:$C,MATCH(F5,รายการวัตถุดิบ!$B:$B,0))) -> ถุงx22.50 | J5: กล่องละ 12 ถุง x 10 kg | K5: 12 | L5: ถุงละ 10 kg
E6: =IF(OR(F6="-",F6=""),"-",INDEX(รายการวัตถุดิบ!$A:$A,MATCH(F6,รายการวัตถุดิบ!$B:$B,0))) -> M03-0013 | F6: แป้งสาลี ตรา"ม้าแดง" | G6: =IF(OR(F6="-",F6=""),"-",INDEX(รายการวัตถุดิบ!$C:$C,MATCH(F6,รายการวัตถุดิบ!$B:$B,0))) -> ถุงx22.50 | J6: ถุงละ 20 kg | K6: 20 | L6: kg
E7: =IF(OR(F7="-",F7=""),"-",INDEX(รายการวัตถุดิบ!$A:$A,MATCH(F7,รายการวัตถุดิบ!$B:$B,0))) -> M03-0014 | F7: แป้งสาลี ตรา "K เหลือง" สูตร 2(ด้ายฟ้าคู่) | G7: =IF(OR(F7="-",F7=""),"-",INDEX(รายการวัตถุดิบ!$C:$C,MATCH(F7,รายการวัตถุดิบ!$B:$B,0))) -> ถุงx22.50 | J7: กล่องละ 24 ถุง x 20 kg | K7: 24 | L7: ถุงละ 20 kg
E8: =IF(OR(F8="-",F8=""),"-",INDEX(รายการวัตถุดิบ!$A:$A,MATCH(F8,รายการวัตถุดิบ!$B:$B,0))) -> M03-0015 | F8: แป้งสาลี (ด้ายน้ำเงิน-ขาว) | G8: =IF(OR(F8="-",F8=""),"-",INDEX(รายการวัตถุดิบ!$C:$C,MATCH(F8,รายการวัตถุดิบ!$B:$B,0))) -> ถุงx22.50
E9: =IF(OR(F9="-",F9=""),"-",INDEX(รายการวัตถุดิบ!$A:$A,MATCH(F9,รายการวัตถุดิบ!$B:$B,0))) -> M03-0016 | F9: แป้งสาลี BFM-G22.50 | G9: =IF(OR(F9="-",F9=""),"-",INDEX(รายการวัตถุดิบ!$C:$C,MATCH(F9,รายการวัตถุดิบ!$B:$B,0))) -> ถุงx22.50
E10: =IF(OR(F10="-",F10=""),"-",INDEX(รายการวัตถุดิบ!$A:$A,MATCH(F10,รายการวัตถุดิบ!$B:$B,0))) -> M03-0019 | F10: แป้งสาลี TFF-GK | G10: =IF(OR(F10="-",F10=""),"-",INDEX(รายการวัตถุดิบ!$C:$C,MATCH(F10,รายการวัตถุดิบ!$B:$B,0))) -> ถุงx22.50
E11: =IF(OR(F11="-",F11=""),"-",INDEX(รายการวัตถุดิบ!$A:$A,MATCH(F11,รายการวัตถุดิบ!$B:$B,0))) -> M03-0021 | F11: แป้งสาลี (White globe) | G11: =IF(OR(F11="-",F11=""),"-",INDEX(รายการวัตถุดิบ!$C:$C,MATCH(F11,รายการวัตถุดิบ!$B:$B,0))) -> ถุงx22.50
E12: =IF(OR(F12="-",F12=""),"-",INDEX(รายการวัตถุดิบ!$A:$A,MATCH(F12,รายการวัตถุดิบ!$B:$B,0))) -> M03-0022 | F12: แป้งสาลี D-1 | G12: =IF(OR(F12="-",F12=""),"-",INDEX(รายการวัตถุดิบ!$C:$C,MATCH(F12,รายการวัตถุดิบ!$B:$B,0))) -> ถุงx22.50
E13: =IF(OR(F13="-",F13=""),"-",INDEX(รายการวัตถุดิบ!$A:$A,MATCH(F13,รายการวัตถุดิบ!$B:$B,0))) -> M03-0023 | F13: แป้งสาลี K-น้ำเงิน | G13: =IF(OR(F13="-",F13=""),"-",INDEX(รายการวัตถุดิบ!$C:$C,MATCH(F13,รายการวัตถุดิบ!$B:$B,0))) -> ถุงx22.50
E14: =IF(OR(F14="-",F14=""),"-",INDEX(รายการวัตถุดิบ!$A:$A,MATCH(F14,รายการวัตถุดิบ!$B:$B,0))) -> M03-0025 | F14: แป้งสาลี KML | G14: =IF(OR(F14="-",F14=""),"-",INDEX(รายการวัตถุดิบ!$C:$C,MATCH(F14,รายการวัตถุดิบ!$B:$B,0))) -> ถุงx22.50
E15: =IF(OR(F15="-",F15=""),"-",INDEX(รายการวัตถุดิบ!$A:$A,MATCH(F15,รายการวัตถุดิบ!$B:$B,0))) -> M03-0025-1 | F15: ทดลอง - แป้งสาลี KML | G15: =IF(OR(F15="-",F15=""),"-",INDEX(รายการวัตถุดิบ!$C:$C,MATCH(F15,รายการวัตถุดิบ!$B:$B,0))) -> ถุงx22.50
E16: =IF(OR(F16="-",F16=""),"-",INDEX(รายการวัตถุดิบ!$A:$A,MATCH(F16,รายการวัตถุดิบ!$B:$B,0))) -> M03-0027 | F16: แป้งสาลี ตราอินทัชน้ำเงิน | G16: =IF(OR(F16="-",F16=""),"-",INDEX(รายการวัตถุดิบ!$C:$C,MATCH(F16,รายการวัตถุดิบ!$B:$B,0))) -> ถุงx22.50
E17: =IF(OR(F17="-",F17=""),"-",INDEX(รายการวัตถุดิบ!$A:$A,MATCH(F17,รายการวัตถุดิบ!$B:$B,0))) -> M03-0028 | F17: แป้งสาลี ตราอินทัชน้ำเงิน 02 | G17: =IF(OR(F17="-",F17=""),"-",INDEX(รายการวัตถุดิบ!$C:$C,MATCH(F17,รายการวัตถุดิบ!$B:$B,0))) -> ถุงx22.50
E18: =IF(OR(F18="-",F18=""),"-",INDEX(รายการวัตถุดิบ!$A:$A,MATCH(F18,รายการวัตถุดิบ!$B:$B,0))) -> WK-2202 | F18: แป้งสาลี - D1 (22.5 Kg.) | G18: =IF(OR(F18="-",F18=""),"-",INDEX(รายการวัตถุดิบ!$C:$C,MATCH(F18,รายการวัตถุดิบ!$B:$B,0))) -> ชุดx22.50 kg.
E19: =IF(OR(F19="-",F19=""),"-",INDEX(รายการวัตถุดิบ!$A:$A,MATCH(F19,รายการวัตถุดิบ!$B:$B,0))) -> WK-2202-1 | F19: แป้งสาลี (18.5 Kg) | G19: =IF(OR(F19="-",F19=""),"-",INDEX(รายการวัตถุดิบ!$C:$C,MATCH(F19,รายการวัตถุดิบ!$B:$B,0))) -> KG
... E21: =IF(OR(F21="-",F21=""),"-",INDEX(รายการวัตถุดิบ!$A:$A,MATCH(F21,รายการวัตถุดิบ!$B:$B,0))) -> WK-2206-1 | F21: แป้งสาลี ตราอินทัชน้ำเงิน (18.50 kg.) | G21: =IF(OR(F21="-",F21=""),"-",INDEX(รายการวัตถุดิบ!$C:$C,MATCH(F21,รายการวัตถุดิบ!$B:$B,0))) -> ชุด/18.50 kg.
E22: =IF(OR(F22="-",F22=""),"-",INDEX(รายการวัตถุดิบ!$A:$A,MATCH(F22,รายการวัตถุดิบ!$B:$B,0))) -> - | G22: =IF(OR(F22="-",F22=""),"-",INDEX(รายการวัตถุดิบ!$C:$C,MATCH(F22,รายการวัตถุดิบ!$B:$B,0))) -> -
E23: =IF(OR(F23="-",F23=""),"-",INDEX(รายการวัตถุดิบ!$A:$A,MATCH(F23,รายการวัตถุดิบ!$B:$B,0))) -> - | G23: =IF(OR(F23="-",F23=""),"-",INDEX(รายการวัตถุดิบ!$C:$C,MATCH(F23,รายการวัตถุดิบ!$B:$B,0))) -> -
E24: =IF(OR(F24="-",F24=""),"-",INDEX(รายการวัตถุดิบ!$A:$A,MATCH(F24,รายการวัตถุดิบ!$B:$B,0))) -> - | G24: =IF(OR(F24="-",F24=""),"-",INDEX(รายการวัตถุดิบ!$C:$C,MATCH(F24,รายการวัตถุดิบ!$B:$B,0))) -> -
E25: =IF(OR(F25="-",F25=""),"-",INDEX(รายการวัตถุดิบ!$A:$A,MATCH(F25,รายการวัตถุดิบ!$B:$B,0))) -> - | G25: =IF(OR(F25="-",F25=""),"-",INDEX(รายการวัตถุดิบ!$C:$C,MATCH(F25,รายการวัตถุดิบ!$B:$B,0))) -> -
E26: =IF(OR(F26="-",F26=""),"-",INDEX(รายการวัตถุดิบ!$A:$A,MATCH(F26,รายการวัตถุดิบ!$B:$B,0))) -> - | G26: =IF(OR(F26="-",F26=""),"-",INDEX(รายการวัตถุดิบ!$C:$C,MATCH(F26,รายการวัตถุดิบ!$B:$B,0))) -> -
E27: =IF(OR(F27="-",F27=""),"-",INDEX(รายการวัตถุดิบ!$A:$A,MATCH(F27,รายการวัตถุดิบ!$B:$B,0))) -> - | G27: =IF(OR(F27="-",F27=""),"-",INDEX(รายการวัตถุดิบ!$C:$C,MATCH(F27,รายการวัตถุดิบ!$B:$B,0))) -> -
E28: =IF(OR(F28="-",F28=""),"-",INDEX(รายการวัตถุดิบ!$A:$A,MATCH(F28,รายการวัตถุดิบ!$B:$B,0))) -> - | G28: =IF(OR(F28="-",F28=""),"-",INDEX(รายการวัตถุดิบ!$C:$C,MATCH(F28,รายการวัตถุดิบ!$B:$B,0))) -> -
E29: =IF(OR(F29="-",F29=""),"-",INDEX(รายการวัตถุดิบ!$A:$A,MATCH(F29,รายการวัตถุดิบ!$B:$B,0))) -> - | G29: =IF(OR(F29="-",F29=""),"-",INDEX(รายการวัตถุดิบ!$C:$C,MATCH(F29,รายการวัตถุดิบ!$B:$B,0))) -> -
E30: =IF(OR(F30="-",F30=""),"-",INDEX(รายการวัตถุดิบ!$A:$A,MATCH(F30,รายการวัตถุดิบ!$B:$B,0))) -> - | G30: =IF(OR(F30="-",F30=""),"-",INDEX(รายการวัตถุดิบ!$C:$C,MATCH(F30,รายการวัตถุดิบ!$B:$B,0))) -> -
